Workbook

Sheet Sheet1
A3: Row Labels | B3: Count of Email
A4: bfre2137@chi.sysco.com | B4: 11
A5: jswe4549@boston.sysco.com | B5: 9
A6: jbow2741@boston.sysco.com | B6: 8
A7: mweb1884@int.sysco.com | B7: 8
A8: kgor4562@sysco.com | B8: 7
A9: dbla0356@mt.sysco.com | B9: 7
A10: jgla2956@metrony.sysco.com | B10: 7
A11: pgra9460@sd.sysco.com | B11: 6
A12: swil2146@cha.sysco.com | B12: 6
A13: khau4953@sfo.sysco.com | B13: 6
A14: hper2530@wcf.sysco.com | B14: 5
A15: snai1403@boston.sysco.com | B15: 5
... A452: jran8733@syr.sysco.com | B452: 1
A453: (blank)
A454: Grand Total | B454: 707

Sheet Tickets
A1: Dispositioned By | B1: Date | C1: Status | D1: Response | E1: Details | F1: Ticket Number | G1: Id | H1: Start time | I1: Completion time | J1: Email | K1: Name | L1: Sysco Sales Consultants email (add multiple with semicolon " ; " ) | M1: Order Number (Marketplace orders begin with the letter "M" or the Item SKU begins with the number "6". Example: #M4c5def9f971d) REQUIRED to process options 1-4. You may put "N/A" for options 5-7 below | N1: I would like to: | O1: Report an Issue with Item Received: Please Insert 3 or more Images showing the damage. All Images should be in "JPEG" format to be accepted by Supplier. Please do not attach movies. | P1: Additional Image of concern (#2) Jpeg format Only | Q1: Additional Image of concern (#3) Jpeg format Only | R1: Report an Issue with Item Received: Please provide a brief on the issue (Item arrived spoiled, damaged, broken, etc) and amount of products impacted out of total | S1: Report an Item not Delivered: Please provide sku "beginning with number "6" and quantity not received. All incidents MUST be reported 30 days from order date for suppliers to process. | T1: Enable or Disable Accounts (Please do not change header of template) | U1: Please add details on product request (fact sheets, availability, matching sets, substitutes, etc) | V1: Enabling/Disabling Account on Marketplace: Please upload an excel or CSV file with the following 3 columns in excel format: (Opco ID | Customer Number | Enable (TRUE)/Disable (FALSE)). Please re | W1: Other: Please Provide details of your inquiry (If there is an issue with the order, you MUST use option #3 and report an incident) | X1: Cancel an Order | Y1: ETA on Delivery (Sysco Shop is NOW enabled to show Delivery Details)
A2: Kashif | D2: We have routed your request to the seller. Please feel free to reach out next week if you do not see an update by then. | E2: Delete | G2: 1 | H2: 46200.646 | I2: 46200.646 | J2: kkhu6683@sysco.com | K2: Kashif Khurshid | L2: =OfficeForms.Table[[#This Row],[Email]] -> kkhu6683@sysco.com | M2: mefksdfrgkrg | N2: Cancel an Order (Marketplace Third Party product orders are not eligible for Returns/Refunds or exchanges and is indicated at time of purchase) | X2: We Can only cancel an order if its in "awaiting acceptance" state and has not been accepted by the Seller. Once the order is accepted, it will no longer be cancellable and rejecting delivery will still hold the customer liable thus please confirm prior to placing any marketplace order. Also note that Sysco Shop does not have the ability to place orders automatically on behalf of customers.
A3: Kashif | E3: Delete | G3: 2 | H3: 46200.65 | I3: 46200.652 | J3: kkhu6683@sysco.com | K3: Kashif Khurshid | L3: =OfficeForms.Table[[#This Row],[Email]] -> kkhu6683@sysco.com | M3: fdhygiiulkfhsd | N3: Report an Issue with an Order Received (All Issues MUST be reported within 14 days of order and submitted with Images and Description of Issue) | O3: https://sysco-my.sharepoint.com/personal/kkhu6683_sysco_com/Documents/Apps/Microsoft%20Forms/Untitled%20form/Question/The%20Caffe%201_Kashif%20Khurshid.jpeg; https://sysco-my.sharepoint.com/personal/kkhu6683_sysco_com/Documents/Apps/Microsoft%20Forms/Untitled%20form/Question/The%20Caffe%202_Kashif%20Khurshid.jpeg | R3: test testinggrhgfhgfhbgfngfb
A4: Kashif | E4: Delete | G4: 3 | H4: 46202.469 | I4: 46202.47 | J4: kkhu6683@sysco.com | K4: Kashif Khurshid | L4: =OfficeForms.Table[[#This Row],[Email]] -> kkhu6683@sysco.com | M4: efewf | N4: 7. Other | W4: dewd
A5: Kashif | E5: Delete | G5: 4 | H5: 46202.47 | I5: 46202.471 | J5: hali8845@corp.sysco.com | K5: Hassan Ali | L5: =OfficeForms.Table[[#This Row],[Email]] -> hali8845@corp.sysco.com | M5: N/A | N5: 1. Receive ETA on Delivery (Marketplace orders have a 5-7 Business Day lead time and currently there is not an option to expedite deliver) | Y5: Marketplace orders have a 5-7 Business Day lead time and currently there is not an option to expedite deliver. Customer is liable for retrieving package if the business is closed or the address is incorrect. Please ensure Delivery address is updated in Salesforce prior to ordering.
A6: Kashif | C6: Sent | D6: We apologize for the inconvenience. A support ticket has been opened with the supplier. Please feel free to reach out if you do not see an activity on your account by next week. | E6: created in Mirakle | G6: 5 | H6: 46202.474 | I6: 46202.477 | J6: wpow2255@sysco.com | K6: Tony Powers | L6: =OfficeForms.Table[[#This Row],[Email]] -> wpow2255@sysco.com | M6: M85a82b1b7b9c | N6: 3. Report an Issue with an Order Received (All Issues MUST be reported within 14 days of order and submitted with Images and Description of Issue) | O6: https://sysco-my.sharepoint.com/personal/kkhu6683_sysco_com/Documents/Apps/Microsoft%20Forms/Untitled%20form/Question/3rdparty3_Tony%20Powers.jpg | P6: https://sysco-my.sharepoint.com/personal/kkhu6683_sysco_com/Documents/Apps/Microsoft%20Forms/Untitled%20form/Report%20an%20Issue%20with%20Item%20Received%20Please%20Insert%203%201/3rdpartyhot_Tony%20Powers.jpg | Q6: https://sysco-my.sharepoint.com/personal/kkhu6683_sysco_com/Documents/Apps/Microsoft%20Forms/Untitled%20form/Report%20an%20Issue%20with%20Item%20Received%20Please%20Insert%203/3rdparty2_Tony%20Powers.jpg | R6: items were received completely thawed and hot. Not safe to serve
A7: Kashif | C7: Sent | D7: We apologize for the inconvenience. A support ticket has been opened with the supplier. Please feel free to reach out if you do not see an activity on your account by next week. | E7: https://syscous-prod.mirakl.net/mmp/operator/order/Mf685c21465c4-A/message?sort=date%2CDESC&limit=25 | G7: 6 | H7: 46202.498 | I7: 46202.504 | J7: hkin1331@kc.sysco.com | K7: Haley King | L7: =OfficeForms.Table[[#This Row],[Email]] -> hkin1331@kc.sysco.com | M7: Mf685c21465c4 | N7: 3. Report an Issue with an Order Received (All Issues MUST be reported within 14 days of order and submitted with Images and Description of Issue) | R7: Not size of product description
A8: Kashif | C8: Sent | D8: We apologize for the inconvenience. A support ticket has been opened with the supplier. Please feel free to reach out if you do not see an activity on your account by next week. | E8: https://syscous-prod.mirakl.net/mmp/operator/order/Mee63e533470c-A/message/bbe15d84-7a18-42d9-9c11-f515ad5be06f/details | G8: 7 | H8: 46202.515 | I8: 46202.516 | J8: pgra9460@sd.sysco.com | K8: Peter Grap | L8: =OfficeForms.Table[[#This Row],[Email]] -> pgra9460@sd.sysco.com | M8: Mee63e533470c | N8: 4. Report an Order not Delivered ( Please note that customer rejecting delivery will suffice as a delivery issue) | S8: SUPC 6022496 Dove choc (2cs) - tracking reports delivered, but customer did not receive. Nobody named 'ibarra' works at this location, and Fedex claimed that was who received the order.
A9: Kashif | C9: Sent | D9: Unfortunately, this order has been processed, and the Seller is unable to cancel. Please note, Marketplace Third Party product orders are not eligible for Returns/Refunds or exchanges and is indicated at time of purchase. We wish we could be of more help but given Marketplace's policy, we are unable to assist further on this order. | G9: 8 | H9: 46202.653 | I9: 46202.656 | J9: nfon6129@emd.sysco.com | K9: Nick Fontana | L9: =OfficeForms.Table[[#This Row],[Email]] -> nfon6129@emd.sysco.com | M9: Mb5a6fa6ccf65 | N9: 2. Cancel an Order (Marketplace Third Party product orders are not eligible for Returns/Refunds or exchanges and is indicated at time of purchase) | X9: We Can only cancel an order if its in "awaiting acceptance" state and has not been accepted by the Seller. Once the order is accepted, it will no longer be cancellable and rejecting delivery will still hold the customer liable thus please confirm prior to placing any marketplace order. Also note that Sysco Shop does not have the ability to place orders automatically on behalf of customers.
A10: Kashif | C10: Sent | D10: We apologize for the inconvenience. A support ticket has been opened with the supplier. Please feel free to reach out if you do not see an activity on your account by next week. | E10: https://syscous-prod.mirakl.net/mmp/operator/order/M4e8180f441d4-A/message/1d20a812-1f34-4962-acc3-7261aeb2e93f/details | G10: 9 | H10: 46202.833 | I10: 46202.838 | J10: jmat3941@int.sysco.com | K10: Jeremy Matthews | L10: =OfficeForms.Table[[#This Row],[Email]] -> jmat3941@int.sysco.com | M10: M4e8180f441d4 | N10: 3. Report an Issue with an Order Received (All Issues MUST be reported within 14 days of order and submitted with Images and Description of Issue) | O10: https://sysco-my.sharepoint.com/personal/kkhu6683_sysco_com/Documents/Apps/Microsoft%20Forms/Untitled%20form/Question/Beignet1_Jeremy%20Matthews.jpg | P10: https://sysco-my.sharepoint.com/personal/kkhu6683_sysco_com/Documents/Apps/Microsoft%20Forms/Untitled%20form/Report%20an%20Issue%20with%20Item%20Received%20Please%20Insert%203%201/beignet3_Jeremy%20Matthews.jpg | Q10: https://sysco-my.sharepoint.com/personal/kkhu6683_sysco_com/Documents/Apps/Microsoft%20Forms/Untitled%20form/Report%20an%20Issue%20with%20Item%20Received%20Please%20Insert%203/Beignet4_Jeremy%20Matthews.jpg | R10: Item arrived thawed and proofed, not frozen.
A11: Kashif | C11: Sent | D11: Unfortunately, this order has been processed, and the Seller is unable to cancel. Please note, Marketplace Third Party product orders are not eligible for Returns/Refunds or exchanges and is indicated at time of purchase. We wish we could be of more help but given Marketplace's policy, we are unable to assist further on this order. | G11: 10 | H11: 46203.391 | I11: 46203.398 | J11: mcan3533@min.sysco.com | K11: Martin Canfield | L11: =OfficeForms.Table[[#This Row],[Email]] -> mcan3533@min.sysco.com | M11: Mc0f2cf114a79 | N11: 7. Other | W11: My customer ordered the wrong size Flavor-Ice. She wanted the 5.5 giant size but ordered the much smaller size which she can't sell. If it was one case, we would ask them to find a way to sell it. But its eight cases and they want to send them back.
A12: Kashif | C12: Sent | D12: We have routed your request to the seller. Please feel free to reach out next week if you do not see an update by then. | E12: https://syscous-prod.mirakl.net/mmp/operator/order/Mffc98f09d1a7-A/message?sort=date%2CDESC&limit=25 | G12: 11 | H12: 46203.423 | I12: 46203.427 | J12: jsca2787@philly.sysco.com | K12: Jennifer Bell | L12: =OfficeForms.Table[[#This Row],[Email]] -> jsca2787@philly.sysco.com | M12: Mffc98f09d1a7 | N12: 3. Report an Issue with an Order Received (All Issues MUST be reported within 14 days of order and submitted with Images and Description of Issue) | O12: https://sysco-my.sharepoint.com/personal/kkhu6683_sysco_com/Documents/Apps/Microsoft%20Forms/Untitled%20form/Question/Malvern%20Mispick_Jennifer%20Bell.jpeg | R12: Ramen noodles received, ordered cheddar crackers - Mispick
A13: Kashif | C13: Sent | D13: Thank you for sharing. Please fill out the form again and select option #3 "issue with order received" and complete the additional details before we can proceed with a ticket | G13: 12 | H13: 46203.448 | I13: 46203.452 | J13: jswe4549@boston.sysco.com | K13: Jean Sweet | L13: =OfficeForms.Table[[#This Row],[Email]] -> jswe4549@boston.sysco.com | M13: Ma825a338a0f6 | N13: 7. Other | W13: Customer received freeze dried apple instead of straw- please issue credit- new cs has be re-ordered
A14: Kashif | C14: Sent | D14: We apologize for the inconvenience. A support ticket has been opened with the supplier. Please feel free to reach out if you do not see an activity on your account by next week. | E14: https://syscous-prod.mirakl.net/mmp/operator/order/M9f8b6d10da2e-A/message?sort=date%2CDESC&limit=25 | G14: 13 | H14: 46203.46 | I14: 46203.465 | J14: acro7701@sysco.com | K14: Alexis Croushore | L14: =OfficeForms.Table[[#This Row],[Email]] -> acro7701@sysco.com | M14: M9f8b6d10da2e | N14: 3. Report an Issue with an Order Received (All Issues MUST be reported within 14 days of order and submitted with Images and Description of Issue) | O14: https://sysco-my.sharepoint.com/personal/kkhu6683_sysco_com/Documents/Apps/Microsoft%20Forms/Untitled%20form/Question/5E439EF2-156A-4C78-91E8-CBBA0E871768_Alexis%20Croushore.png | P14: https://sysco-my.sharepoint.com/personal/kkhu6683_sysco_com/Documents/Apps/Microsoft%20Forms/Untitled%20form/Report%20an%20Issue%20with%20Item%20Received%20Please%20Insert%203%201/IMG_4678_Alexis%20Croushore.PNG | R14: Some lids do not fit the cups, some lids no not have holes. Wants to return 6/6 cases , 308.87 total.
A15: Kashif | C15: New | D15: We have routed your request to the seller. Please feel free to reach out next week if you do not see an update by then. | G15: 14 | H15: 46203.508 | I15: 46203.51 | J15: sriz5487@shr.sysco.com | K15: Stefanie Rizzo-Zahn | L15: =OfficeForms.Table[[#This Row],[Email]] -> sriz5487@shr.sysco.com | M15: #M827c03c17592 | N15: 7. Other (Do NOT use for Order/Product Related Issues) | W15: Customer needs to order the top for this portion cup. Please help assist what that item is so we can get it ordered
A16: Kashif | C16: Sent | D16: We apologize for the inconvenience. A support ticket has been opened with the supplier. Please feel free to reach out if you do not see an activity on your account by next week. | E16: https://syscous-prod.mirakl.net/mmp/operator/order/Mbc51e08c2606-A/message?sort=date%2CDESC&limit=25 | G16: 15 | H16: 46203.555 | I16: 46203.559 | J16: blin7890@ntx.sysco.com | K16: Lin John | L16: =OfficeForms.Table[[#This Row],[Email]] -> blin7890@ntx.sysco.com | M16: Mbc51e08c2606-A | N16: 3. Report an Issue with an Order Received (All Issues MUST be reported within 14 days of order and submitted with Images and Description of Issue) | O16: https://sysco-my.sharepoint.com/personal/kkhu6683_sysco_com/Documents/Apps/Microsoft%20Forms/Untitled%20form/Question/Image%20(72)_Lin%20John.jpg; https://sysco-my.sharepoint.com/personal/kkhu6683_sysco_com/Documents/Apps/Microsoft%20Forms/Untitled%20form/Question/image%20(21)_Lin%20John.png | R16: 3 leaked or broken bottle pf passion fruit syrup
A17: Kashif | C17: Sent | D17: Unfortunately, this order has been processed, and the Seller is unable to cancel. Please note, Marketplace Third Party product orders are not eligible for Returns/Refunds or exchanges and is indicated at time of purchase. We wish we could be of more help but given Marketplace's policy, we are unable to assist further on this order. | G17: 16 | H17: 46203.571 | I17: 46203.572 | J17: jswe4549@boston.sysco.com | K17: Jean Sweet | L17: =OfficeForms.Table[[#This Row],[Email]] -> jswe4549@boston.sysco.com | M17: Me1135712a256 | N17: 7. Other (Do NOT use for Order/Product Related Issues) | W17: Customer ordered in error- SC has called the MFG and they said they can return- please advise on a return label
A18: Kashif | C18: Sent | D18: We have routed your request to the seller. Please feel free to reach out next week if you do not see an update by then. | E18: https://syscous-prod.mirakl.net/mmp/operator/order/Mad6533fba6f2-A/message?sort=date%2CDESC&limit=25 | G18: 17 | H18: 46203.647 | I18: 46203.648 | J18: cwar7858@ctx.sysco.com | K18: Charlie Ward | L18: =OfficeForms.Table[[#This Row],[Email]] -> cwar7858@ctx.sysco.com | M18: Mad6533fba6f2 | N18: 7. Other (Do NOT use for Order/Product Related Issues) | W18: UPS says it has attempted to deliver twice but business was closed. business was NOT closed, employees were inside. Please leave notes to try harder or simply leave the package, that is fine per customer
A19: Kashif | C19: Sent | D19: Unfortunately, this order has been processed, and the Seller is unable to cancel. Please note, Marketplace Third Party product orders are not eligible for Returns/Refunds or exchanges and is indicated at time of purchase. We wish we could be of more help but given Marketplace's policy, we are unable to assist further on this order. | G19: 18 | H19: 46203.744 | I19: 46203.746 | J19: pste6327@mt.sysco.com | K19: Paul Stelmack | L19: =OfficeForms.Table[[#This Row],[Email]] -> pste6327@mt.sysco.com | M19: M346b5eb63018 | N19: 7. Other (Do NOT use for Order/Product Related Issues) | W19: This customer says he did not mean to order this, asked for a return, can we credit back at all? Sorry new account learning the ropes
A20: Kashif | C20: Sent | D20: Thank you for sharing, If you do not see activity on your account by next week, please reach back out. | E20: https://syscous-prod.mirakl.net/mmp/operator/order/Mf21fe5c2517b-A/message/e5b4c079-e8cd-43fb-8c45-a9747ba2dd33/details | G20: 19 | H20: 46203.788 | I20: 46203.792 | J20: ggal6788@rs.sysco.com | K20: Gustavo Galvez | L20: =OfficeForms.Table[[#This Row],[Email]] -> ggal6788@rs.sysco.com | M20: Mf21fe5c2517b | N20: 4. Report an Order not Delivered ( Please note that customer rejecting delivery will suffice as a delivery issue) | S20: 6064771; 6064775
A21: Kashif | C21: New | D21: We have routed your request to the seller. Please feel free to reach out next week if you do not see an update by then. | G21: 20 | H21: 46204.301 | I21: 46204.302 | J21: acar1081@rnc.sysco.com | K21: Aileen Carr | L21: =OfficeForms.Table[[#This Row],[Email]] -> acar1081@rnc.sysco.com | M21: na | N21: 7. Other (Do NOT use for Order/Product Related Issues) | W21: Are these items available yet on Marketplace? https://everydaysupplyco.com/search?sort_by=relevance&q=just&type=product&filter.p.t.category=fb-1-16&filter.v.price.gte=&filter.v.price.lte= https://everydaysupplyco.com/search?sort_by=relevance&q=just&type=product&filter.p.t.category=fb-1-16&filter.v.price.gte=&filter.v.price.lte=
A22: Kashif | C22: Sent | D22: It appears to have been delivered. The seller has completed the order from their end and wish we could assist further. I would encourage the seller to connect directly with the delivery provider. | G22: 21 | H22: 46204.36 | I22: 46204.364 | J22: fmem6919@corp.sysco.com | K22: Fredy Membreno | L22: =OfficeForms.Table[[#This Row],[Email]] -> fmem6919@corp.sysco.com | M22: M4c5def9f971d | N22: 1. Receive ETA on Delivery (Marketplace orders have a 5-7 Business Day lead time and currently there is not an option to expedite deliver) | Y22: Marketplace orders have a 5-7 Business Day lead time and currently there is not an option to expedite deliver. Customer is liable for retrieving package if the business is closed or the address is incorrect. Please ensure Delivery address is updated in Salesforce prior to ordering.
A23: Kashif | C23: Sent | D23: We have enabled these customer account to view and order Marketplace Third Party Products. Please note it will take about 24 hours to take effect. | G23: 22 | H23: 46204.381 | I23: 46204.383 | J23: smoo5472@wmn.sysco.com | K23: Shane Moore | L23: =OfficeForms.Table[[#This Row],[Email]] -> smoo5472@wmn.sysco.com | M23: 047-933682 Cru Restaurant (enable) | N23: 6. Enable/Disable Customer for Marketplace Products (All TRS customers are enabled by default, LCC and CMU may have restrictions, please confirm prior to requesting)
A24: Kashif | C24: Sent | D24: Unfortunately this Marketplace sellers does not offer samples at this time. | G24: 23 | H24: 46204.425 | I24: 46204.426 | J24: kgwa2062@balt.sysco.com | K24: Karim Gwaduri | L24: =OfficeForms.Table[[#This Row],[Email]] -> kgwa2062@balt.sysco.com | M24: 012-241715 | N24: 5. Information on Product/Supplier (Please provide SUPC number that begins with "6xxxxxx" | U24: a new client of mine is looking to sample item 6066520. there is no SC information on shop so i don't know who to contact. please provide me with contact information so i can reach out to the broker or PSA or just let me know if we are able to send a free sample to them. thank you!
A25: Kashif | C25: Sent | D25: It appears to have been delivered. The seller has completed the order from their end and wish we could assist further. I would encourage the seller to connect directly with the delivery provider. | G25: 24 | H25: 46204.535 | I25: 46204.537 | J25: kelt9557@la.sysco.com | K25: Kirsten Eltzholtz | L25: =OfficeForms.Table[[#This Row],[Email]] -> kelt9557@la.sysco.com | M25: MD832AFB41047 | N25: 3. Report an Issue with an Order Received (All Issues MUST be reported within 14 days of order and submitted with Images and Description of Issue) | R25: The customer ordered the wrong product and does not want it.
A26: Kashif | C26: Sent | D26: We have routed your request to the seller. Please feel free to reach out next week if you do not see an update by then. | G26: 25 | H26: 46204.617 | I26: 46204.618 | J26: pgra9460@sd.sysco.com | K26: Peter Grap | L26: =OfficeForms.Table[[#This Row],[Email]] -> pgra9460@sd.sysco.com | M26: n/a | N26: 5. Information on Product/Supplier (Please provide SUPC number that begins with "6xxxxxx" | U26: Customer reports that item 6086673 (prevail jerky) may have the pack size & contents listed incorrectly. Please advise on the correct pack size that will be shipped for this item.
A27: Kashif | C27: Sent | D27: Unfortunately, this order has been processed, and the Seller is unable to cancel. Please note, Marketplace Third Party product orders are not eligible for Returns/Refunds or exchanges and is indicated at time of purchase. We wish we could be of more help but given Marketplace's policy, we are unable to assist further on this order. | G27: 26 | H27: 46204.627 | I27: 46204.628 | J27: gner8973@sfl.sysco.com | K27: Giselle Neri | L27: =OfficeForms.Table[[#This Row],[Email]] -> gner8973@sfl.sysco.com | M27: Mc8050f9d386e | N27: 2. Cancel an Order (Marketplace Third Party product orders are not eligible for Returns/Refunds or exchanges and is indicated at time of purchase) | X27: We Can only cancel an order if its in "awaiting acceptance" state and has not been accepted by the Seller. Once the order is accepted, it will no longer be cancellable and rejecting delivery will still hold the customer liable thus please confirm prior to placing any marketplace order. Also note that Sysco Shop does not have the ability to place orders automatically on behalf of customers.
A28: Kashif | C28: New | D28: We have routed your request to the seller. Please feel free to reach out next week if you do not see an update by then. | G28: 27 | H28: 46204.718 | I28: 46204.721 | J28: kkuz3544@sd.sysco.com | K28: Kristen Kuznicki | L28: =OfficeForms.Table[[#This Row],[Email]] -> kkuz3544@sd.sysco.com | M28: 036-744930 - not an order inquiry | N28: 7. Other (Do NOT use for Order/Product Related Issues) | W28: Hello, I tried e-mailing & sent pics but I see there is no where to include them here. I am trying to locate two Karat products: 20oz white paper bowl (#10009400) and the lid for it (karat #c-kdl142-pp/10390300). The #'s starting w/1's are what the customer sent. TY for your help!
A29: Kashif | C29: Escalate | D29: We have routed your request to the seller. Please feel free to reach out next week if you do not see an update by then. | G29: 28 | H29: 46204.878 | I29: 46204.88 | J29: jgla2956@metrony.sysco.com | K29: Justin Glasser | L29: =OfficeForms.Table[[#This Row],[Email]] -> jgla2956@metrony.sysco.com | M29: M59c6fe193ab, M439221894fd4, M44c96521c56c, Mb59b4691f145, M659c3273e591. This customer is fraud and we need to cancel orders immediately and halt shipping. | N29: 2. Cancel an Order (Marketplace Third Party product orders are not eligible for Returns/Refunds or exchanges and is indicated at time of purchase) | X29: We Can only cancel an order if its in "awaiting acceptance" state and has not been accepted by the Seller. Once the order is accepted, it will no longer be cancellable and rejecting delivery will still hold the customer liable thus please confirm prior to placing any marketplace order. Also note that Sysco Shop does not have the ability to place orders automatically on behalf of customers.
A30: Kashif | C30: Sent | D30: We apologize for the inconvenience. A support ticket has been opened with the supplier. Please feel free to reach out if you do not see an activity on your account by next week. | E30: https://syscous-prod.mirakl.net/mmp/operator/order/M43dee9a2bcff-A/message?sort=date%2CDESC&limit=25 | G30: 29 | H30: 46205.532 | I30: 46205.541 | J30: jswe4549@boston.sysco.com | K30: Jean Sweet | L30: =OfficeForms.Table[[#This Row],[Email]] -> jswe4549@boston.sysco.com | M30: M43dee9a2bcff | N30: 3. Report an Issue with an Order Received (All Issues MUST be reported within 14 days of order and submitted with Images and Description of Issue) | O30: https://sysco-my.sharepoint.com/personal/kkhu6683_sysco_com/Documents/Apps/Microsoft%20Forms/Untitled%20form/Question/loafy%20mispick_Jean%20Sweet.jpg | P30: https://sysco-my.sharepoint.com/personal/kkhu6683_sysco_com/Documents/Apps/Microsoft%20Forms/Untitled%20form/Report%20an%20Issue%20with%20Item%20Received%20Please%20Insert%203%201/loafy%202_Jean%20Sweet.jpg | Q30: https://sysco-my.sharepoint.com/personal/kkhu6683_sysco_com/Documents/Apps/Microsoft%20Forms/Untitled%20form/Report%20an%20Issue%20with%20Item%20Received%20Please%20Insert%203/loafy%20mispick_Jean%20Sweet.jpg | R30: Good afternoon, Our customer ordered 3rd party strawberry freeze dried but received apple instead they need a credit please- - the got apple freeze dried
A31: Kashif | C31: Sent | D31: It appears that the ticket is incomplete, Please fill it out again and be sure to complete all information required for us to Process. | G31: 30 | H31: 46205.553 | I31: 46205.557 | J31: pgra9460@sd.sysco.com | K31: Peter Grap | L31: =OfficeForms.Table[[#This Row],[Email]] -> pgra9460@sd.sysco.com | M31: Customer 036-501692 (east mesa central #23) | invoice 136A4288M (120cs Kize brownie) | N31: 1. Receive ETA on Delivery (Marketplace orders have a 5-7 Business Day lead time and currently there is not an option to expedite deliver) | Y31: Marketplace orders have a 5-7 Business Day lead time and currently there is not an option to expedite deliver. Customer is liable for retrieving package if the business is closed or the address is incorrect. Please ensure Delivery address is updated in Salesforce prior to ordering.
A32: Kashif | C32: Sent | G32: 31 | H32: 46205.576 | I32: 46205.577 | J32: tbru0701@rnc.sysco.com | K32: Thomas Bruner | L32: =OfficeForms.Table[[#This Row],[Email]] -> tbru0701@rnc.sysco.com | M32: 137-695638 | N32: 5. Information on Product/Supplier (Please provide SUPC number that begins with "6xxxxxx" | U32: Is item #6070014 available in full sugar? Not sugar free?
A33: Kashif | C33: Sent | D33: This item is currently out of stock and the seller does not have an ETA on its availability yet. If you do not see this back on after 2 weeks, please feel free to reach out to us. | G33: 32 | H33: 46205.64 | I33: 46205.641 | J33: afeo2641@wcf.sysco.com | K33: Aniello Feola | L33: =OfficeForms.Table[[#This Row],[Email]] -> afeo2641@wcf.sysco.com | M33: . | N33: 5. Information on Product/Supplier (Please provide SUPC number that begins with "6xxxxxx" | U33: 6056985 When will this product be available again?
A34: Kashif | C34: Sent | D34: We apologize for the inconvenience. A support ticket has been opened with the supplier. Please feel free to reach out if you do not see an activity on your account by next week. | E34: https://syscous-prod.mirakl.net/mmp/operator/order/M1e95df72e263-A/message?sort=date%2CDESC&limit=25 | G34: 33 | H34: 46205.695 | I34: 46205.703 | J34: mmor7615@lv.sysco.com | K34: Manuel Moreno | L34: =OfficeForms.Table[[#This Row],[Email]] -> mmor7615@lv.sysco.com | M34: M1e95df72e263 | N34: 3. Report an Issue with an Order Received (All Issues MUST be reported within 14 days of order and submitted with Images and Description of Issue) | O34: https://sysco-my.sharepoint.com/personal/kkhu6683_sysco_com/Documents/Apps/Microsoft%20Forms/Untitled%20form/Question/Dragon%20Ridge%203rd%20party%20Spoiled%20Mushroom%202_Manuel%20Moreno.jpeg; https://sysco-my.sharepoint.com/personal/kkhu6683_sysco_com/Documents/Apps/Microsoft%20Forms/Untitled%20form/Question/Dragon%20Ridge%203rd%20party%20Spoiled%20Mushroom_Manuel%20Moreno.jpeg | R34: The item arrived spoiled. The mushroom was not able to breathe and was wet and slimy
A35: Kashif | C35: Sent | D35: Unfortunately, this order has been processed, and the Seller is unable to cancel. Please note, Marketplace Third Party product orders are not eligible for Returns/Refunds or exchanges and is indicated at time of purchase. We wish we could be of more help but given Marketplace's policy, we are unable to assist further on this order. | G35: 34 | H35: 46206.049 | I35: 46206.051 | J35: emar1379@va.sysco.com | K35: Ever Martinez | L35: =OfficeForms.Table[[#This Row],[Email]] -> emar1379@va.sysco.com | M35: M692433f9aa33 | N35: 2. Cancel an Order (Marketplace Third Party product orders are not eligible for Returns/Refunds or exchanges and is indicated at time of purchase) | X35: We Can only cancel an order if its in "awaiting acceptance" state and has not been accepted by the Seller. Once the order is accepted, it will no longer be cancellable and rejecting delivery will still hold the customer liable thus please confirm prior to placing any marketplace order. Also note that Sysco Shop does not have the ability to place orders automatically on behalf of customers.
A36: Kashif | C36: Sent | D36: We have routed your request to the seller. Please feel free to reach out next week if you do not see an update by then. | E36: It Appears the item was damaged in Transit. We have reached out to the Seller to proceed with a refund. https://www.fedex.com/fedextrack/?trknbr=510032640802&trkqual=12030~510032640802~FDEG | G36: 35 | H36: 46208.567 | I36: 46208.568 | J36: cmcc9289@int.sysco.com | K36: Charles McClellan | L36: =OfficeForms.Table[[#This Row],[Email]] -> cmcc9289@int.sysco.com | M36: M1fcbf9ab2aa5 | N36: 1. Receive ETA on Delivery (Marketplace orders have a 5-7 Business Day lead time and currently there is not an option to expedite deliver) | Y36: Marketplace orders have a 5-7 Business Day lead time and currently there is not an option to expedite deliver. Customer is liable for retrieving package if the business is closed or the address is incorrect. Please ensure Delivery address is updated in Salesforce prior to ordering.
A37: Kashif | C37: Sent | D37: It does appear to have inventory. Please ensure the account being used is located in united states and has access to marketplace products. There are times where Suppliers limit the geos they serve which may impact what customers can see and purchase. | E37: GTIN 10815812014131 Alternate Product ID 10815812014131 Manufacturer Product Code 815812014134 | G37: 36 | H37: 46208.65 | I37: 46208.657 | J37: sriz5487@shr.sysco.com | K37: Stefanie Rizzo-Zahn | L37: =OfficeForms.Table[[#This Row],[Email]] -> sriz5487@shr.sysco.com | M37: #M827c03c17592 | N37: 3. Report an Issue with an Order Received (All Issues MUST be reported within 14 days of order and submitted with Images and Description of Issue) | R37: Customer received this item but needs to order the lid for this portion cup and it's not available to order on Sysco Marketplace. Order 872894788129 The lid is Matching Lid: FP-PL400-PET can you help me find this item in Syco Shop so I can order for the customer please
A38: Kashif | C38: Sent | D38: Thank you for sharing. We have reached out to the seller and have created a support ticket. Please feel free to reach out to us next week if you do not see any activity on this order. | E38: https://syscous-prod.mirakl.net/mmp/operator/order/M3f64100d26ca-A/message/03d9c98f-56e4-4887-a3a1-31b4724f22ac/details | G38: 37 | H38: 46209.362 | I38: 46209.363 | J38: ckne2908@boston.sysco.com | K38: Christopher Knell | L38: =OfficeForms.Table[[#This Row],[Email]] -> ckne2908@boston.sysco.com | M38: M3f64100d26ca | N38: 4. Report an Order not Delivered ( Please note that customer rejecting delivery will suffice as a delivery issue) | S38: 6020888 - 1 not received
A39: Kashif | C39: Sent | D39: Marketplace has a policy for reporting any incidents to the seller within the first 14 days of delivery. Any incidents such as these should be reported within that timeframe so that we may open a support ticket with the seller. Unfortunately, this falls outside of the allotted time and thus we are unable to assist further. | E39: https://tools.usps.com/tracking/9434636106196334818968 | F39: https://tools.usps.com/tracking/9434636106196334818968 | G39: 38 | H39: 46209.38 | I39: 46209.388 | J39: tmey5037@indy.sysco.com | K39: Tammy Meyer | L39: =OfficeForms.Table[[#This Row],[Email]] -> tmey5037@indy.sysco.com | M39: M98fe533adb93 | N39: 4. Report an Order not Delivered ( Please note that customer rejecting delivery will suffice as a delivery issue) | S39: 6063641-1 6063646-1 6063652-1
A40: Kashif | C40: Sent | D40: Unfortunately, this order has been processed, and the Seller is unable to cancel. Please note, Marketplace Third Party product orders are not eligible for Returns/Refunds or exchanges and is indicated at time of purchase. We wish we could be of more help but given Marketplace's policy, we are unable to assist further on this order. | G40: 39 | H40: 46209.548 | I40: 46209.55 | J40: jswe4549@boston.sysco.com | K40: Jean Sweet | L40: =OfficeForms.Table[[#This Row],[Email]] -> jswe4549@boston.sysco.com | M40: 156B3431M Date: 5/23/26 | N40: 3. Report an Issue with an Order Received (All Issues MUST be reported within 14 days of order and submitted with Images and Description of Issue) | R40: This was order was refused upon delivery so now we need a credit for 45.43. INV 1556B3431M
...

Sheet Standard Responses
A3: Category | B3: Message response
A4: General | B4: We have routed your request to the seller. Please feel free to reach out next week if you do not see an update by then.
A5: General | B5: Thank you for sharing, If you do not see activity on your account by next week, please reach back out.
A6: Incident | B6: We apologize for the inconvenience. A support ticket has been opened with the supplier. Please feel free to reach out if you do not see an activity on your account by next week.
A7: Availability | B7: This item is currently out of stock and the seller does not have an ETA on its availability yet. If you do not see this back on after 2 weeks, please feel free to reach out to us.
A8: Availability | B8: Yes, they appear online and should be available through Sysco Shop.
A9: Availability | B9: We have routed your request to the seller for product availability. Please feel free to reach out next week if you do not see an update by then.
A10: Availability | B10: It does appear to have inventory. Please ensure the account being used is located in united states and has access to marketplace products. There are times where Suppliers limit the geos they serve which may impact what customers can see and purchase.
A11: Seller Info | B11: We typically don’t share seller contact info and prefer a single tone when engaging with the seller. That said, is there anything you like us to communicate with the seller.
A12: Product Inquiry | B12: Can you please advise what info/support is needed regarding these products below? We typically do not give out supplier information, but are able to communicate with them on your behalf.
A13: Cancel | B13: Unfortunately, this order has been processed, and the Seller is unable to cancel. Please note, Marketplace Third Party product orders are not eligible for Returns/Refunds or exchanges and is indicated at time of purchase. We wish we could be of more help but given Marketplace's policy, we are unable to assist further on this order.
A14: Incident | B14: Thank you for sharing. We have reached out to the seller and have created a support ticket. Please feel free to reach out to us next week if you do not see any activity on this order.
... A26: Incomplete Info | B26: It appears that the ticket is incomplete, Please fill it out again and be sure to complete all information required for us to Process.
A50: Status
A51: Delete
A52: New
A53: Ready
A54: Sent
A55: Escalate
A56: Close

Sheet EmailDrafts
A1: Status | B1: Incident # | C1: Send To | D1: Subject | E1: Body
A2: Sent | B2: =Tickets!G6 -> 5 | D2: =CONCATENATE("Incident Regarding ", Tickets!M6) -> Incident Regarding M85a82b1b7b9c | E2: =CONCATENATE("Hi, ",Tickets!D6," Additional Detail (if Any:) ",Tickets!E6,"."," Thanks, Marketplace Support Team") -> Hi, We apologize for the inconvenience. A support ticket has been opened with the supplier. Please feel free to reach out if you do not see an activity on your account by next week. Additional Detail (if Any:) created in Mirakle. Thanks, Marketplace Support Team
A3: Sent | B3: =Tickets!G7 -> 6 | C3: =Tickets!L7 | D3: =CONCATENATE("Incident Regarding ", Tickets!M7) -> Incident Regarding Mf685c21465c4 | E3: =CONCATENATE("Hi, ",Tickets!D7," Additional Detail (if Any:) ",Tickets!E7,"."," Thanks, Marketplace Support Team") -> Hi, We apologize for the inconvenience. A support ticket has been opened with the supplier. Please feel free to reach out if you do not see an activity on your account by next week. Additional Detail (if Any:) https://syscous-prod.mirakl.net/mmp/operator/order/Mf685c21465c4-A/message?sort=date%2CDESC&limit=25. Thanks, Marketplace Support Team
A4: Sent | B4: =Tickets!G8 -> 7 | C4: =Tickets!L8 -> pgra9460@sd.sysco.com | D4: =CONCATENATE("Incident Regarding ", Tickets!M8) -> Incident Regarding Mee63e533470c | E4: =CONCATENATE("Hi, ",Tickets!D8," Additional Detail (if Any:) ",Tickets!E8,"."," Thanks, Marketplace Support Team") -> Hi, We apologize for the inconvenience. A support ticket has been opened with the supplier. Please feel free to reach out if you do not see an activity on your account by next week. Additional Detail (if Any:) https://syscous-prod.mirakl.net/mmp/operator/order/Mee63e533470c-A/message/bbe15d84-7a18-42d9-9c11-f515ad5be06f/details. Thanks, Marketplace Support Team
A5: Sent | B5: =Tickets!G9 -> 8 | C5: =Tickets!L9 -> nfon6129@emd.sysco.com | D5: =CONCATENATE("Incident Regarding ", Tickets!M9) -> Incident Regarding Mb5a6fa6ccf65 | E5: =CONCATENATE("Hi, ",Tickets!D9," Additional Detail (if Any:) ",Tickets!E9,"."," Thanks, Marketplace Support Team") -> Hi, Unfortunately, this order has been processed, and the Seller is unable to cancel. Please note, Marketplace Third Party product orders are not eligible for Returns/Refunds or exchanges and is indicated at time of purchase. We wish we could be of more help but given Marketplace's policy, we are unable to assist further on this order. Additional Detail (if Any:) . Thanks, Marketplace Support Team
A6: Sent | B6: =Tickets!G10 -> 9 | C6: =Tickets!L10 -> jmat3941@int.sysco.com | D6: =CONCATENATE("Incident Regarding ", Tickets!M10) -> Incident Regarding M4e8180f441d4 | E6: =CONCATENATE("Hi, ",Tickets!D10," Additional Detail (if Any:) ",Tickets!E10,"."," Thanks, Marketplace Support Team") -> Hi, We apologize for the inconvenience. A support ticket has been opened with the supplier. Please feel free to reach out if you do not see an activity on your account by next week. Additional Detail (if Any:) https://syscous-prod.mirakl.net/mmp/operator/order/M4e8180f441d4-A/message/1d20a812-1f34-4962-acc3-7261aeb2e93f/details. Thanks, Marketplace Support Team
A7: Sent | B7: =Tickets!G11 -> 10 | C7: =Tickets!L11 -> mcan3533@min.sysco.com | D7: =CONCATENATE("Incident Regarding ", Tickets!M11) -> Incident Regarding Mc0f2cf114a79 | E7: =CONCATENATE("Hi, ",Tickets!D11," Additional Detail (if Any:) ",Tickets!E11,"."," Thanks, Marketplace Support Team") -> Hi, Unfortunately, this order has been processed, and the Seller is unable to cancel. Please note, Marketplace Third Party product orders are not eligible for Returns/Refunds or exchanges and is indicated at time of purchase. We wish we could be of more help but given Marketplace's policy, we are unable to assist further on this order. Additional Detail (if Any:) . Thanks, Marketplace Support Team
A8: Sent | B8: =Tickets!G12 -> 11 | C8: =Tickets!L12 -> jsca2787@philly.sysco.com | D8: =CONCATENATE("Incident Regarding ", Tickets!M12) -> Incident Regarding Mffc98f09d1a7 | E8: =CONCATENATE("Hi, ",Tickets!D12," Additional Detail (if Any:) ",Tickets!E12,"."," Thanks, Marketplace Support Team") -> Hi, We have routed your request to the seller. Please feel free to reach out next week if you do not see an update by then. Additional Detail (if Any:) https://syscous-prod.mirakl.net/mmp/operator/order/Mffc98f09d1a7-A/message?sort=date%2CDESC&limit=25. Thanks, Marketplace Support Team
A9: Sent | B9: =Tickets!G13 -> 12 | C9: =Tickets!L13 -> jswe4549@boston.sysco.com | D9: =CONCATENATE("Incident Regarding ", Tickets!M13) -> Incident Regarding Ma825a338a0f6 | E9: =CONCATENATE("Hi, ",Tickets!D13," Additional Detail (if Any:) ",Tickets!E13,"."," Thanks, Marketplace Support Team") -> Hi, Thank you for sharing. Please fill out the form again and select option #3 "issue with order received" and complete the additional details before we can proceed with a ticket Additional Detail (if Any:) . Thanks, Marketplace Support Team
A10: Sent | B10: =Tickets!G14 -> 13 | C10: =Tickets!L14 -> acro7701@sysco.com | D10: =CONCATENATE("Incident Regarding ", Tickets!M14) -> Incident Regarding M9f8b6d10da2e | E10: =CONCATENATE("Hi, ",Tickets!D14," Additional Detail (if Any:) ",Tickets!E14,"."," Thanks, Marketplace Support Team") -> Hi, We apologize for the inconvenience. A support ticket has been opened with the supplier. Please feel free to reach out if you do not see an activity on your account by next week. Additional Detail (if Any:) https://syscous-prod.mirakl.net/mmp/operator/order/M9f8b6d10da2e-A/message?sort=date%2CDESC&limit=25. Thanks, Marketplace Support Team
A11: Sent | B11: =Tickets!G15 -> 14 | C11: =Tickets!L15 -> sriz5487@shr.sysco.com | D11: =CONCATENATE("Incident Regarding ", Tickets!M15) -> Incident Regarding #M827c03c17592 | E11: =CONCATENATE("Hi, ",Tickets!D15," Additional Detail (if Any:) ",Tickets!E15,"."," Thanks, Marketplace Support Team") -> Hi, We have routed your request to the seller. Please feel free to reach out next week if you do not see an update by then. Additional Detail (if Any:) . Thanks, Marketplace Support Team
A12: Sent | B12: =Tickets!G16 -> 15 | C12: =Tickets!L16 -> blin7890@ntx.sysco.com | D12: =CONCATENATE("Incident Regarding ", Tickets!M16) -> Incident Regarding Mbc51e08c2606-A | E12: =CONCATENATE("Hi, ",Tickets!D16," Additional Detail (if Any:) ",Tickets!E16,"."," Thanks, Marketplace Support Team") -> Hi, We apologize for the inconvenience. A support ticket has been opened with the supplier. Please feel free to reach out if you do not see an activity on your account by next week. Additional Detail (if Any:) https://syscous-prod.mirakl.net/mmp/operator/order/Mbc51e08c2606-A/message?sort=date%2CDESC&limit=25. Thanks, Marketplace Support Team
A13: Sent | B13: =Tickets!G17 -> 16 | C13: =Tickets!L17 -> jswe4549@boston.sysco.com | D13: =CONCATENATE("Incident Regarding ", Tickets!M17) -> Incident Regarding Me1135712a256 | E13: =CONCATENATE("Hi, ",Tickets!D17," Additional Detail (if Any:) ",Tickets!E17,"."," Thanks, Marketplace Support Team") -> Hi, Unfortunately, this order has been processed, and the Seller is unable to cancel. Please note, Marketplace Third Party product orders are not eligible for Returns/Refunds or exchanges and is indicated at time of purchase. We wish we could be of more help but given Marketplace's policy, we are unable to assist further on this order. Additional Detail (if Any:) . Thanks, Marketplace Support Team
A14: Sent | B14: =Tickets!G18 -> 17 | C14: =Tickets!j6 | D14: =CONCATENATE("Incident Regarding ", Tickets!M18) -> Incident Regarding Mad6533fba6f2 | E14: =CONCATENATE("Hi, ",Tickets!D18," Additional Detail (if Any:) ",Tickets!E18,"."," Thanks, Marketplace Support Team") -> Hi, We have routed your request to the seller. Please feel free to reach out next week if you do not see an update by then. Additional Detail (if Any:) https://syscous-prod.mirakl.net/mmp/operator/order/Mad6533fba6f2-A/message?sort=date%2CDESC&limit=25. Thanks, Marketplace Support Team
A15: Sent | B15: =Tickets!G19 -> 18 | C15: =Tickets!L19 -> pste6327@mt.sysco.com | D15: =CONCATENATE("Incident Regarding ", Tickets!M19) -> Incident Regarding M346b5eb63018 | E15: =CONCATENATE("Hi, ",Tickets!D19," Additional Detail (if Any:) ",Tickets!E19,"."," Thanks, Marketplace Support Team") -> Hi, Unfortunately, this order has been processed, and the Seller is unable to cancel. Please note, Marketplace Third Party product orders are not eligible for Returns/Refunds or exchanges and is indicated at time of purchase. We wish we could be of more help but given Marketplace's policy, we are unable to assist further on this order. Additional Detail (if Any:) . Thanks, Marketplace Support Team
A16: Sent | B16: =Tickets!G20 -> 19 | C16: =Tickets!L20 -> ggal6788@rs.sysco.com | D16: =CONCATENATE("Incident Regarding ", Tickets!M20) -> Incident Regarding Mf21fe5c2517b | E16: =CONCATENATE("Hi, ",Tickets!D20," Additional Detail (if Any:) ",Tickets!E20,"."," Thanks, Marketplace Support Team") -> Hi, Thank you for sharing, If you do not see activity on your account by next week, please reach back out. Additional Detail (if Any:) https://syscous-prod.mirakl.net/mmp/operator/order/Mf21fe5c2517b-A/message/e5b4c079-e8cd-43fb-8c45-a9747ba2dd33/details. Thanks, Marketplace Support Team
A17: Sent | B17: =Tickets!G21 -> 20 | C17: =Tickets!L21 -> acar1081@rnc.sysco.com | D17: =CONCATENATE("Incident Regarding ", Tickets!M21) -> Incident Regarding na | E17: =CONCATENATE("Hi, ",Tickets!D21," Additional Detail (if Any:) ",Tickets!E21,"."," Thanks, Marketplace Support Team") -> Hi, We have routed your request to the seller. Please feel free to reach out next week if you do not see an update by then. Additional Detail (if Any:) . Thanks, Marketplace Support Team
A18: Sent | B18: =Tickets!G22 -> 21 | C18: =Tickets!L22 -> fmem6919@corp.sysco.com | D18: =CONCATENATE("Incident Regarding ", Tickets!M22) -> Incident Regarding M4c5def9f971d | E18: =CONCATENATE("Hi, ",Tickets!D22," Additional Detail (if Any:) ",Tickets!E22,"."," Thanks, Marketplace Support Team") -> Hi, It appears to have been delivered. The seller has completed the order from their end and wish we could assist further. I would encourage the seller to connect directly with the delivery provider. Additional Detail (if Any:) . Thanks, Marketplace Support Team
A19: Sent | B19: =Tickets!G23 -> 22 | C19: =Tickets!L23 -> smoo5472@wmn.sysco.com | D19: =CONCATENATE("Incident Regarding ", Tickets!M23) -> Incident Regarding 047-933682 Cru Restaurant (enable) | E19: =CONCATENATE("Hi, ",Tickets!D23," Additional Detail (if Any:) ",Tickets!E23,"."," Thanks, Marketplace Support Team") -> Hi, We have enabled these customer account to view and order Marketplace Third Party Products. Please note it will take about 24 hours to take effect. Additional Detail (if Any:) . Thanks, Marketplace Support Team
A20: Sent | B20: =Tickets!G24 -> 23 | C20: =Tickets!L24 -> kgwa2062@balt.sysco.com | D20: =CONCATENATE("Incident Regarding ", Tickets!M24) -> Incident Regarding 012-241715 | E20: =CONCATENATE("Hi, ",Tickets!D24," Additional Detail (if Any:) ",Tickets!E24,"."," Thanks, Marketplace Support Team") -> Hi, Unfortunately this Marketplace sellers does not offer samples at this time. Additional Detail (if Any:) . Thanks, Marketplace Support Team
A21: Sent | B21: =Tickets!G25 -> 24 | C21: =Tickets!L25 -> kelt9557@la.sysco.com | D21: =CONCATENATE("Incident Regarding ", Tickets!M25) -> Incident Regarding MD832AFB41047 | E21: =CONCATENATE("Hi, ",Tickets!D25," Additional Detail (if Any:) ",Tickets!E25,"."," Thanks, Marketplace Support Team") -> Hi, It appears to have been delivered. The seller has completed the order from their end and wish we could assist further. I would encourage the seller to connect directly with the delivery provider. Additional Detail (if Any:) . Thanks, Marketplace Support Team
A22: Sent | B22: =Tickets!G26 -> 25 | C22: =Tickets!L26 -> pgra9460@sd.sysco.com | D22: =CONCATENATE("Incident Regarding ", Tickets!M26) -> Incident Regarding n/a | E22: =CONCATENATE("Hi, ",Tickets!D26," Additional Detail (if Any:) ",Tickets!E26,"."," Thanks, Marketplace Support Team") -> Hi, We have routed your request to the seller. Please feel free to reach out next week if you do not see an update by then. Additional Detail (if Any:) . Thanks, Marketplace Support Team
A23: Sent | B23: =Tickets!G27 -> 26 | C23: =Tickets!L27 -> gner8973@sfl.sysco.com | D23: =CONCATENATE("Incident Regarding ", Tickets!M27) -> Incident Regarding Mc8050f9d386e | E23: =CONCATENATE("Hi, ",Tickets!D27," Additional Detail (if Any:) ",Tickets!E27,"."," Thanks, Marketplace Support Team") -> Hi, Unfortunately, this order has been processed, and the Seller is unable to cancel. Please note, Marketplace Third Party product orders are not eligible for Returns/Refunds or exchanges and is indicated at time of purchase. We wish we could be of more help but given Marketplace's policy, we are unable to assist further on this order. Additional Detail (if Any:) . Thanks, Marketplace Support Team
A24: Sent | B24: =Tickets!G28 -> 27 | C24: =Tickets!L28 -> kkuz3544@sd.sysco.com | D24: =CONCATENATE("Incident Regarding ", Tickets!M28, " and Ticket #",Tickets!G28) -> Incident Regarding 036-744930 - not an order inquiry and Ticket #27 | E24: =CONCATENATE("Hi, ",Tickets!D28," Additional Detail (if Any:) ",Tickets!E28,"."," Thanks, Marketplace Support Team") -> Hi, We have routed your request to the seller. Please feel free to reach out next week if you do not see an update by then. Additional Detail (if Any:) . Thanks, Marketplace Support Team
A25: Sent | B25: =Tickets!G29 -> 28 | C25: =Tickets!L29 -> jgla2956@metrony.sysco.com | D25: =CONCATENATE("Incident Regarding ", Tickets!M29, " and Ticket #",Tickets!G29) -> Incident Regarding M59c6fe193ab, M439221894fd4, M44c96521c56c, Mb59b4691f145, M659c3273e591. This customer is fraud and we need to cancel orders immediately and halt shipping. and Ticket #28 | E25: =CONCATENATE("Hi, ",Tickets!D29," Additional Detail (if Any:) ",Tickets!E29,"."," Thanks, Marketplace Support Team") -> Hi, We have routed your request to the seller. Please feel free to reach out next week if you do not see an update by then. Additional Detail (if Any:) . Thanks, Marketplace Support Team
A26: Sent | B26: =Tickets!#REF! -> #REF! | C26: =Tickets!L30 -> jswe4549@boston.sysco.com | D26: =CONCATENATE("Incident Regarding ", Tickets!M30, " and Ticket #",Tickets!G30) -> Incident Regarding M43dee9a2bcff and Ticket #29 | E26: =CONCATENATE("Hi, ",Tickets!D30," Additional Detail (if Any:) ",Tickets!E30,"."," Thanks, Marketplace Support Team") -> Hi, We apologize for the inconvenience. A support ticket has been opened with the supplier. Please feel free to reach out if you do not see an activity on your account by next week. Additional Detail (if Any:) https://syscous-prod.mirakl.net/mmp/operator/order/M43dee9a2bcff-A/message?sort=date%2CDESC&limit=25. Thanks, Marketplace Support Team
A27: Sent | B27: =Tickets!#REF! -> #REF! | C27: =Tickets!L31 -> pgra9460@sd.sysco.com | D27: =CONCATENATE("Incident Regarding ", Tickets!M31, " and Ticket #",Tickets!G31) -> Incident Regarding Customer 036-501692 (east mesa central #23) | invoice 136A4288M (120cs Kize brownie) and Ticket #30 | E27: =CONCATENATE("Hi, ",Tickets!D31," Additional Detail (if Any:) ",Tickets!E31,"."," Thanks, Marketplace Support Team") -> Hi, It appears that the ticket is incomplete, Please fill it out again and be sure to complete all information required for us to Process. Additional Detail (if Any:) . Thanks, Marketplace Support Team
A28: Sent | B28: =Tickets!#REF! -> #REF! | C28: =Tickets!L32 -> tbru0701@rnc.sysco.com | D28: =CONCATENATE("Incident Regarding ", Tickets!M32, " and Ticket #",Tickets!G32) -> Incident Regarding 137-695638 and Ticket #31 | E28: =CONCATENATE("Hi, ",Tickets!D32," Additional Detail (if Any:) ",Tickets!E32,"."," Thanks, Marketplace Support Team") -> Hi, Additional Detail (if Any:) . Thanks, Marketplace Support Team
A29: Sent | B29: =Tickets!#REF! -> #REF! | C29: =Tickets!L33 -> afeo2641@wcf.sysco.com | D29: =CONCATENATE("Incident Regarding ", Tickets!M33, " and Ticket #",Tickets!G33) -> Incident Regarding . and Ticket #32 | E29: =CONCATENATE("Hi, ",Tickets!D33," Additional Detail (if Any:) ",Tickets!E33,"."," Thanks, Marketplace Support Team") -> Hi, This item is currently out of stock and the seller does not have an ETA on its availability yet. If you do not see this back on after 2 weeks, please feel free to reach out to us. Additional Detail (if Any:) . Thanks, Marketplace Support Team
A30: Sent | B30: =Tickets!#REF! -> #REF! | C30: =Tickets!L34 -> mmor7615@lv.sysco.com | D30: =CONCATENATE("Incident Regarding ", Tickets!M34, " and Ticket #",Tickets!G34) -> Incident Regarding M1e95df72e263 and Ticket #33 | E30: =CONCATENATE("Hi, ",Tickets!D34," Additional Detail (if Any:) ",Tickets!E34,"."," Thanks, Marketplace Support Team") -> Hi, We apologize for the inconvenience. A support ticket has been opened with the supplier. Please feel free to reach out if you do not see an activity on your account by next week. Additional Detail (if Any:) https://syscous-prod.mirakl.net/mmp/operator/order/M1e95df72e263-A/message?sort=date%2CDESC&limit=25. Thanks, Marketplace Support Team
A31: Sent | B31: =Tickets!#REF! -> #REF! | C31: =Tickets!L35 -> emar1379@va.sysco.com | D31: =CONCATENATE("Incident Regarding ", Tickets!M35, " and Ticket #",Tickets!G35) -> Incident Regarding M692433f9aa33 and Ticket #34 | E31: =CONCATENATE("Hi, ",Tickets!D35," Additional Detail (if Any:) ",Tickets!E35,"."," Thanks, Marketplace Support Team") -> Hi, Unfortunately, this order has been processed, and the Seller is unable to cancel. Please note, Marketplace Third Party product orders are not eligible for Returns/Refunds or exchanges and is indicated at time of purchase. We wish we could be of more help but given Marketplace's policy, we are unable to assist further on this order. Additional Detail (if Any:) . Thanks, Marketplace Support Team
A32: Sent | B32: =Tickets!#REF! -> #REF! | C32: =Tickets!L36 -> cmcc9289@int.sysco.com | D32: =CONCATENATE("Incident Regarding ", Tickets!M36, " and Ticket #",Tickets!G36) -> Incident Regarding M1fcbf9ab2aa5 and Ticket #35 | E32: =CONCATENATE("Hi, ",Tickets!D36," Additional Detail (if Any:) ",Tickets!E36,"."," Thanks, Marketplace Support Team") -> Hi, We have routed your request to the seller. Please feel free to reach out next week if you do not see an update by then. Additional Detail (if Any:) It Appears the item was damaged in Transit. We have reached out to the Seller to proceed with a refund. https://www.fedex.com/fedextrack/?trknbr=510032640802&trkqual=12030~510032640802~FDEG. Thanks, Marketplace Support Team
A33: Sent | B33: =Tickets!#REF! -> #REF! | C33: =Tickets!L37 -> sriz5487@shr.sysco.com | D33: =CONCATENATE("Incident Regarding ", Tickets!M37, " and Ticket #",Tickets!G37) -> Incident Regarding #M827c03c17592 and Ticket #36 | E33: =CONCATENATE("Hi, ",Tickets!D37," Additional Detail (if Any:) ",Tickets!E37,"."," Thanks, Marketplace Support Team") -> Hi, It does appear to have inventory. Please ensure the account being used is located in united states and has access to marketplace products. There are times where Suppliers limit the geos they serve which may impact what customers can see and purchase. Additional Detail (if Any:) GTIN 10815812014131 Alternate Product ID 10815812014131 Manufacturer Product Code 815812014134. Thanks, Marketplace Support Team
A34: Sent | B34: =Tickets!#REF! -> #REF! | C34: =Tickets!L38 -> ckne2908@boston.sysco.com | D34: =CONCATENATE("Incident Regarding ", Tickets!M38, " and Ticket #",Tickets!G38) -> Incident Regarding M3f64100d26ca and Ticket #37 | E34: =CONCATENATE("Hi, ",Tickets!D38," Additional Detail (if Any:) ",Tickets!E38,"."," Thanks, Marketplace Support Team") -> Hi, Thank you for sharing. We have reached out to the seller and have created a support ticket. Please feel free to reach out to us next week if you do not see any activity on this order. Additional Detail (if Any:) https://syscous-prod.mirakl.net/mmp/operator/order/M3f64100d26ca-A/message/03d9c98f-56e4-4887-a3a1-31b4724f22ac/details. Thanks, Marketplace Support Team
A35: Sent | B35: =Tickets!#REF! -> #REF! | C35: =Tickets!L39 -> tmey5037@indy.sysco.com | D35: =CONCATENATE("Incident Regarding ", Tickets!M39, " and Ticket #",Tickets!G39) -> Incident Regarding M98fe533adb93 and Ticket #38 | E35: =CONCATENATE("Hi, ",Tickets!D39," Additional Detail (if Any:) ",Tickets!E39,"."," Thanks, Marketplace Support Team") -> Hi, Marketplace has a policy for reporting any incidents to the seller within the first 14 days of delivery. Any incidents such as these should be reported within that timeframe so that we may open a support ticket with the seller. Unfortunately, this falls outside of the allotted time and thus we are unable to assist further. Additional Detail (if Any:) https://tools.usps.com/tracking/9434636106196334818968. Thanks, Marketplace Support Team
A36: Sent | B36: =Tickets!#REF! -> #REF! | C36: =Tickets!L40 -> jswe4549@boston.sysco.com | D36: =CONCATENATE("Incident Regarding ", Tickets!M40, " and Ticket #",Tickets!G40) -> Incident Regarding 156B3431M Date: 5/23/26 and Ticket #39 | E36: =CONCATENATE("Hi, ",Tickets!D40," Additional Detail (if Any:) ",Tickets!E40,"."," Thanks, Marketplace Support Team") -> Hi, Unfortunately, this order has been processed, and the Seller is unable to cancel. Please note, Marketplace Third Party product orders are not eligible for Returns/Refunds or exchanges and is indicated at time of purchase. We wish we could be of more help but given Marketplace's policy, we are unable to assist further on this order. Additional Detail (if Any:) . Thanks, Marketplace Support Team
A37: Sent | B37: =Tickets!#REF! -> #REF! | C37: =Tickets!L41 -> fsta4629@boston.sysco.com | D37: =CONCATENATE("Incident Regarding ", Tickets!M41, " and Ticket #",Tickets!G41) -> Incident Regarding 056174743 Wright in my Kitchen and Ticket #40 | E37: =CONCATENATE("Hi, ",Tickets!D41," Additional Detail (if Any:) ",Tickets!E41,"."," Thanks, Marketplace Support Team") -> Hi, It appears that the ticket is incomplete, Please fill it out again and be sure to complete all information required for us to Process. Additional Detail (if Any:) . Thanks, Marketplace Support Team
... A41: Sent | B41: =Tickets!#REF! -> #REF! | C41: =Tickets!L45 -> bfre2137@chi.sysco.com | D41: =CONCATENATE("Incident Regarding ", Tickets!M45, " and Ticket #",Tickets!G45) -> Incident Regarding M3e2405e7b36a and Ticket #44 | E41: =CONCATENATE("Hi, ",Tickets!D45," Additional Detail (if Any:) ",Tickets!E45,"."," Thanks, Marketplace Support Team") -> Hi, Marketplace orders have a 5-7 Business Day lead time and currently there is not an option to expedite delivery. Additional Detail (if Any:) ups.com/track?tracknum=1Z2XJ4490325109134. Thanks, Marketplace Support Team
